Workbook

Sheet Navigasi
A1: 1. DESKRIPSI USAHA | K1: [TANGGAL]
A2: 1 | B2: Nama Usaha | C2: [NAMA USAHA ANDA] | E2: 3 | F2: Domisili | H2: [DOMISILI USAHA] | I2: 6 | J2: Nama Direktur | K2: [NAMA DIREKTUR]
A3: 2 | B3: Deskripsi Usaha | C3: [INDUSTRI USAHA ANDA] | E3: 4 | F3: Cakupan | H3: Nasional | I3: 7 | J3: Jumlah Karyawan | K3: 6-10 orang
B4: BERFOKUS PADA PENGEMBANGAN KEWIRAUSAHAAN | E4: 5 | F4: Model Usaha | H4: B2C | I4: 8 | J4: Link Website | K4: [LINK WEBSITE]
A6: 2. SUMBER PERMODALAN | F6: 3. TARGET USAHA
A7: 1 | B7: Investasi Modal | C7: 0 | D7: Mandiri | F7: Target Penerimaan Akumulatif selama 3 tahun | J7: (36 bulan) | K7: 0
A8: 2 | B8: Pinjaman Modal | C8: 0 | D8: Bank | F8: % Kontribusi setiap tahun demi mencapai target penerimaan akumulatif 3 tahun
F9: % Kontribusi Tahun 1 | H9: 0 | J9: =SUM(H9:H11) -> 0 | K9: =K7*H9 -> 0
A10: 4. ASUMSI-ASUMSI | F10: % Kontribusi Tahun 2 | H10: 0 | K10: =K7*H10 -> 0
A11: 1 | B11: Pembeli Tahun 1 | C11: 0 | D11: 7. Bunga Pinjaman | F11: % Kontribusi Tahun 3 | H11: 0 | K11: =K7*H11 -> 0
A12: 2 | B12: Tarif Pajak | C12: 0 | D12: 0 | F12: Nilai Tukar $1 | J12: 0 | K12: =K7/J12 -> #DIV/0!
A13: 3 | B13: Peningkatan Biaya tahun 2 | C13: 0 | D13: 8. Asset Non Fisik
A14: 4 | B14: Peningkatan Biaya tahun 3 | C14: 0 | D14: 0 | F14: 8.BIAYA TIDAK LANGSUNG | L14: 7. % KONTRIBUSI
A15: 5 | B15: Amortisasi Asset Non Fisik | C15: 0 | D15: 9. Asst Fisik | F15: No | G15: NAMA BIAYA TIDAK LANGSUNG | J15: Rerata per bulan | L15: PENERIMAAN (BULAN)
A16: 6 | B16: Depresiasi Asset Fisik | C16: 0 | D16: 0 | F16: 1 | G16: Biaya Akuisisi Pelanggan | J16: 0 | L16: JANUARI | M16: 0
F17: 2 | G17: Biaya Gaji | J17: 0 | L17: FEBRUARI | M17: 0
A18: 5.PRODUK/JASA/LAYANAN | F18: 3 | J18: 0 | L18: MARET | M18: 0
A19: Nama Produk | C19: Harga Jual per unit | D19: % Kontribusi | F19: 4 | J19: 0 | L19: APRIL | M19: 0
A20: 1 | C20: 0 | D20: 0 | F20: 5 | J20: 0 | L20: MEI | M20: 0
A21: 2 | C21: 0 | D21: 0 | F21: 6 | J21: 0 | L21: JUNI | M21: 0
A22: 3 | C22: 0 | D22: 0 | F22: 7 | J22: 0 | L22: JULI | M22: 0
A23: 4 | C23: 0 | D23: 0 | F23: 8 | J23: 0 | L23: AGUSTUS | M23: 0
A24: 5 | C24: 0 | D24: 0 | F24: 9 | J24: 0 | L24: SEPTEMBER | M24: 0
D25: =SUM(D20:D24) -> 0 | G25: TOTAL | J25: =SUM(J16:J24) -> 0 | L25: OKTOBER | M25: 0
L26: NOVEMBER | M26: 0
A27: 6.BIAYA LANGSUNG PER UNIT | L27: DESEMBER | M27: 0
B28: NAMA BIAYA LANGSUNG | C28: =B20 -> 0 | D28: =B21 -> 0 | E28: =B22 -> 0 | H28: =B23 -> 0 | I28: =B24 -> 0 | M28: =SUM(M16:M27) -> 0
B29: Harga Jual Per Unit | C29: =C20 -> 0 | D29: =C21 -> 0 | E29: =C22 -> 0 | H29: =C23 -> 0 | I29: =C24 -> 0
A30: 1 | C30: 0 | D30: 0 | E30: 0 | H30: 0 | I30: 0 | L30: 9. Dibuat oleh
A31: 2 | C31: 0 | D31: 0 | E31: 0 | H31: 0 | I31: 0 | L31: =K2 -> [NAMA DIREKTUR]
A32: 3 | C32: 0 | D32: 0 | E32: 0 | H32: 0 | I32: 0 | L32: =H2 -> [DOMISILI USAHA]
A33: 4 | C33: 0 | D33: 0 | E33: 0 | H33: 0 | I33: 0
A34: 5 | C34: 0 | D34: 0 | E34: 0 | H34: 0 | I34: 0
B35: Total Biaya Langsung | C35: =SUM(C30:C34) -> 0 | D35: =SUM(D30:D34) -> 0 | E35: =SUM(E30:E34) -> 0 | H35: =SUM(H30:H34) -> 0 | I35: =SUM(I30:I34) -> 0
B36: Keuntungan Kotor per unit | C36: =C29-C35 -> 0 | D36: =D29-D35 -> 0 | E36: =E29-E35 -> 0 | H36: =H29-H35 -> 0 | I36: =I29-I35 -> 0 | L36: =K1 -> [TANGGAL]
A37: Data hanya untuk simulasi semata dan tidak menggambarkan kondisi keuangan perusahaan sesungguhnya. Model simulasi dibuat oleh Dr.Dion Dewa Barata untuk Wadhwani Foundation Indonesia
B39: TARGET PENJUALAN TAHUN PERTAMA | F39: POTENSI PENDAPATAN
B40: =B20 -> 0 | C40: =Processing!K36 -> #DIV/0! | D40: Unit | F40: Tahun Pertama | H40: =Processing!E36 -> 0 | K40: ≈ | L40: =H40/J12 -> #DIV/0!
B41: =B21 -> 0 | C41: =Processing!L36 -> #DIV/0! | D41: Unit | F41: Tahun Kedua | H41: =Processing!F36 -> 0 | K41: ≈ | L41: =H41/J12 -> #DIV/0!
B42: =B22 -> 0 | C42: =Processing!M36 -> #DIV/0! | D42: Unit | F42: Tahun Ketiga | H42: =Processing!G36 -> 0 | K42: ≈ | L42: =H42/J12 -> #DIV/0!
...

Sheet Proyeksi Arus Kas
B1: PROYEKSI ARUS KAS (TAHUN 1) | L1: =Navigasi!L36 -> [TANGGAL] | N1: PROYEKSI ARUS KAS (TAHUN 2) | X1: =L1 -> [TANGGAL] | Z1: PROYEKSI ARUS KAS (TAHUN 3) | AJ1: =X1 -> [TANGGAL] | AM1: REKAPITULASI ARUS KAS
A2: =Navigasi!C2 -> [NAMA USAHA ANDA] | N2: =A2 -> [NAMA USAHA ANDA] | Z2: =N2 -> [NAMA USAHA ANDA] | AM2: =Z2 -> [NAMA USAHA ANDA]
A3: =Navigasi!H2 -> [DOMISILI USAHA] | N3: =A3 -> [DOMISILI USAHA] | Z3: =N3 -> [DOMISILI USAHA] | AM3: =Z3 -> [DOMISILI USAHA]
B4: =Navigasi!L16 -> JANUARI | C4: =Navigasi!L17 -> FEBRUARI | D4: =Navigasi!L18 -> MARET | E4: =Navigasi!L19 -> APRIL | F4: =Navigasi!L20 -> MEI | G4: =Navigasi!L21 -> JUNI | H4: =Navigasi!L22 -> JULI | I4: =Navigasi!L23 -> AGUSTUS | J4: =Navigasi!L24 -> SEPTEMBER | K4: =Navigasi!L25 -> OKTOBER | L4: =Navigasi!L26 -> NOVEMBER | M4: =Navigasi!L27 -> DESEMBER | N4: =B4 -> JANUARI | O4: =C4 -> FEBRUARI | P4: =D4 -> MARET | Q4: =E4 -> APRIL | R4: =F4 -> MEI | S4: =G4 -> JUNI | T4: =H4 -> JULI | U4: =I4 -> AGUSTUS | ... AK4: =Y4 -> DESEMBER | AM4: TOTAL | AN4: TAHUN 1 | AO4: TAHUN 2 | AP4: TAHUN 3
A5: PENERIMAAN BERSIH
A6: =Processing!C5 -> 0 | B6: =Processing!E5*Processing!E24 -> 0 | C6: =Processing!E5*Processing!E25 -> 0 | D6: =Processing!E26*Processing!E5 -> 0 | E6: =Processing!E5*Processing!E27 -> 0 | F6: =Processing!E5*Processing!E28 -> 0 | G6: =Processing!E5*Processing!E29 -> 0 | H6: =Processing!E30*Processing!E5 -> 0 | I6: =Processing!E5*Processing!E31 -> 0 | J6: =Processing!E5*Processing!E32 -> 0 | K6: =Processing!E5*Processing!E33 -> 0 | L6: =Processing!E5*Processing!E34 -> 0 | M6: =Processing!E5*Processing!E35 -> 0 | N6: =Processing!E5*Processing!F24 -> 0 | O6: =Processing!E5*Processing!F25 -> 0 | P6: =Processing!E5*Processing!F26 -> 0 | Q6: =Processing!E5*Processing!F27 -> 0 | R6: =Processing!E5*Processing!F28 -> 0 | S6: =Processing!E5*Processing!F29 -> 0 | T6: =Processing!E5*Processing!F30 -> 0 | U6: =Processing!E5*Processing!F31 -> 0 | V6: =Processing!E5*Processing!F32 -> 0 | W6: =Processing!E5*Processing!F33 -> 0 | X6: =Processing!E5*Processing!F34 -> 0 | Y6: =Processing!E5*Processing!F35 -> 0 | Z6: =Processing!E5*Processing!G24 -> 0 | AA6: =Processing!E5*Processing!G25 -> 0 | AB6: =Processing!E5*Processing!G26 -> 0 | AC6: =Processing!E5*Processing!G27 -> 0 | AD6: =Processing!E5*Processing!G28 -> 0 | AE6: =Processing!E5*Processing!G29 -> 0 | AF6: =Processing!E5*Processing!G30 -> 0 | AG6: =Processing!E5*Processing!G31 -> 0 | AH6: =Processing!E5*Processing!G32 -> 0 | AI6: =Processing!E5*Processing!G33 -> 0 | AJ6: =Processing!E5*Processing!G34 -> 0 | AK6: =Processing!E5*Processing!G35 -> 0 | AM6: =SUM(B6:AK6) -> 0 | AN6: =SUM(B6:M6) -> 0 | AO6: =SUM(N6:Y6) -> 0 | AP6: =SUM(Z6:AK6) -> 0
A7: =Processing!C6 -> 0 | B7: =Processing!E6*Processing!E24 -> 0 | C7: =Processing!E6*Processing!E25 -> 0 | D7: =Processing!E6*Processing!E26 -> 0 | E7: =Processing!E6*Processing!E27 -> 0 | F7: =Processing!E6*Processing!E28 -> 0 | G7: =Processing!E6*Processing!E29 -> 0 | H7: =Processing!E6*Processing!E30 -> 0 | I7: =Processing!E6*Processing!E31 -> 0 | J7: =Processing!E6*Processing!E32 -> 0 | K7: =Processing!E6*Processing!E33 -> 0 | L7: =Processing!E6*Processing!E34 -> 0 | M7: =Processing!E6*Processing!E35 -> 0 | N7: =Processing!E6*Processing!F24 -> 0 | O7: =Processing!E6*Processing!F25 -> 0 | P7: =Processing!E6*Processing!F26 -> 0 | Q7: =Processing!E6*Processing!F27 -> 0 | R7: =Processing!E6*Processing!F28 -> 0 | S7: =Processing!E6*Processing!F29 -> 0 | T7: =Processing!E6*Processing!F30 -> 0 | U7: =Processing!E6*Processing!F31 -> 0 | V7: =Processing!E6*Processing!F32 -> 0 | W7: =Processing!E6*Processing!F33 -> 0 | X7: =Processing!E6*Processing!F34 -> 0 | Y7: =Processing!E6*Processing!F35 -> 0 | Z7: =Processing!E6*Processing!G24 -> 0 | AA7: =Processing!E6*Processing!G25 -> 0 | AB7: =Processing!E6*Processing!G26 -> 0 | AC7: =Processing!E6*Processing!G27 -> 0 | AD7: =Processing!E6*Processing!G28 -> 0 | AE7: =Processing!E6*Processing!G29 -> 0 | AF7: =Processing!E6*Processing!G30 -> 0 | AG7: =Processing!E6*Processing!G31 -> 0 | AH7: =Processing!E6*Processing!G32 -> 0 | AI7: =Processing!E6*Processing!G33 -> 0 | AJ7: =Processing!E6*Processing!G34 -> 0 | AK7: =Processing!E6*Processing!G35 -> 0 | AM7: =SUM(B7:AK7) -> 0 | AN7: =SUM(B7:M7) -> 0 | AO7: =SUM(N7:Y7) -> 0 | AP7: =SUM(Z7:AK7) -> 0
A8: =Processing!C7 -> 0 | B8: =Processing!E7*Processing!E24 -> 0 | C8: =Processing!E7*Processing!E25 -> 0 | D8: =Processing!E7*Processing!E26 -> 0 | E8: =Processing!E7*Processing!E27 -> 0 | F8: =Processing!E7*Processing!E28 -> 0 | G8: =Processing!E7*Processing!E29 -> 0 | H8: =Processing!E7*Processing!E30 -> 0 | I8: =Processing!E7*Processing!E31 -> 0 | J8: =Processing!E7*Processing!E32 -> 0 | K8: =Processing!E7*Processing!E33 -> 0 | L8: =Processing!E7*Processing!E34 -> 0 | M8: =Processing!E7*Processing!E35 -> 0 | N8: =Processing!E7*Processing!F24 -> 0 | O8: =Processing!E7*Processing!F25 -> 0 | P8: =Processing!E7*Processing!F26 -> 0 | Q8: =Processing!E7*Processing!F27 -> 0 | R8: =Processing!E7*Processing!F28 -> 0 | S8: =Processing!E7*Processing!F29 -> 0 | T8: =Processing!E7*Processing!F30 -> 0 | U8: =Processing!E7*Processing!F31 -> 0 | V8: =Processing!E7*Processing!F32 -> 0 | W8: =Processing!E7*Processing!F33 -> 0 | X8: =Processing!E7*Processing!F34 -> 0 | Y8: =Processing!E7*Processing!F35 -> 0 | Z8: =Processing!E7*Processing!G24 -> 0 | AA8: =Processing!E7*Processing!G25 -> 0 | AB8: =Processing!E7*Processing!G26 -> 0 | AC8: =Processing!E7*Processing!G27 -> 0 | AD8: =Processing!E7*Processing!G28 -> 0 | AE8: =Processing!E7*Processing!G29 -> 0 | AF8: =Processing!E7*Processing!G30 -> 0 | AG8: =Processing!E7*Processing!G31 -> 0 | AH8: =Processing!E7*Processing!G32 -> 0 | AI8: =Processing!E7*Processing!G33 -> 0 | AJ8: =Processing!E7*Processing!G34 -> 0 | AK8: =Processing!E7*Processing!G35 -> 0 | AM8: =SUM(B8:AK8) -> 0 | AN8: =SUM(B8:M8) -> 0 | AO8: =SUM(N8:Y8) -> 0 | AP8: =SUM(Z8:AK8) -> 0
A9: =Processing!C8 -> 0 | B9: =Processing!E8*Processing!E24 -> 0 | C9: =Processing!E8*Processing!E25 -> 0 | D9: =Processing!E8*Processing!E26 -> 0 | E9: =Processing!E8*Processing!E27 -> 0 | F9: =Processing!E8*Processing!E28 -> 0 | G9: =Processing!E8*Processing!E29 -> 0 | H9: =Processing!E8*Processing!E30 -> 0 | I9: =Processing!E8*Processing!E31 -> 0 | J9: =Processing!E8*Processing!E32 -> 0 | K9: =Processing!E8*Processing!E33 -> 0 | L9: =Processing!E8*Processing!E34 -> 0 | M9: =Processing!E7*Processing!E35 -> 0 | N9: =Processing!E8*Processing!F24 -> 0 | O9: =Processing!E8*Processing!F25 -> 0 | P9: =Processing!E8*Processing!F26 -> 0 | Q9: =Processing!E8*Processing!F27 -> 0 | R9: =Processing!E8*Processing!F28 -> 0 | S9: =Processing!E8*Processing!F29 -> 0 | T9: =Processing!E8*Processing!F30 -> 0 | U9: =Processing!E8*Processing!F31 -> 0 | V9: =Processing!E8*Processing!F32 -> 0 | W9: =Processing!E8*Processing!F33 -> 0 | X9: =Processing!E8*Processing!F34 -> 0 | Y9: =Processing!E8*Processing!F35 -> 0 | Z9: =Processing!E8*Processing!G24 -> 0 | AA9: =Processing!E8*Processing!G25 -> 0 | AB9: =Processing!E8*Processing!G26 -> 0 | AC9: =Processing!E8*Processing!G27 -> 0 | AD9: =Processing!E8*Processing!G28 -> 0 | AE9: =Processing!E8*Processing!G29 -> 0 | AF9: =Processing!E8*Processing!G30 -> 0 | AG9: =Processing!E8*Processing!G31 -> 0 | AH9: =Processing!E8*Processing!G32 -> 0 | AI9: =Processing!E8*Processing!G33 -> 0 | AJ9: =Processing!E8*Processing!G34 -> 0 | AK9: =Processing!E8*Processing!G35 -> 0 | AM9: =SUM(B9:AK9) -> 0 | AN9: =SUM(B9:M9) -> 0 | AO9: =SUM(N9:Y9) -> 0 | AP9: =SUM(Z9:AK9) -> 0
A10: =Processing!C9 -> 0 | B10: =Processing!E9*Processing!E24 -> 0 | C10: =Processing!E9*Processing!E25 -> 0 | D10: =Processing!E9*Processing!E26 -> 0 | E10: =Processing!E9*Processing!E27 -> 0 | F10: =Processing!E9*Processing!E28 -> 0 | G10: =Processing!E9*Processing!E29 -> 0 | H10: =Processing!E9*Processing!E30 -> 0 | I10: =Processing!E9*Processing!E31 -> 0 | J10: =Processing!E9*Processing!E32 -> 0 | K10: =Processing!E9*Processing!E33 -> 0 | L10: =Processing!E9*Processing!E34 -> 0 | M10: =Processing!E9*Processing!E35 -> 0 | N10: =Processing!E9*Processing!F24 -> 0 | O10: =Processing!E9*Processing!F25 -> 0 | P10: =Processing!E9*Processing!F26 -> 0 | Q10: =Processing!E9*Processing!F27 -> 0 | R10: =Processing!E9*Processing!F28 -> 0 | S10: =Processing!E9*Processing!F29 -> 0 | T10: =Processing!E9*Processing!F30 -> 0 | U10: =Processing!E9*Processing!F31 -> 0 | V10: =Processing!E9*Processing!F32 -> 0 | W10: =Processing!E9*Processing!F33 -> 0 | X10: =Processing!E9*Processing!F34 -> 0 | Y10: =Processing!E9*Processing!F35 -> 0 | Z10: =Processing!E9*Processing!G24 -> 0 | AA10: =Processing!E9*Processing!G25 -> 0 | AB10: =Processing!E9*Processing!G26 -> 0 | AC10: =Processing!E9*Processing!G27 -> 0 | AD10: =Processing!E9*Processing!G28 -> 0 | AE10: =Processing!E9*Processing!G29 -> 0 | AF10: =Processing!E9*Processing!G30 -> 0 | AG10: =Processing!E9*Processing!G31 -> 0 | AH10: =Processing!E9*Processing!G32 -> 0 | AI10: =Processing!E9*Processing!G33 -> 0 | AJ10: =Processing!E9*Processing!G34 -> 0 | AK10: =Processing!E9*Processing!G35 -> 0 | AM10: =SUM(B10:AK10) -> 0 | AN10: =SUM(B10:M10) -> 0 | AO10: =SUM(N10:Y10) -> 0 | AP10: =SUM(Z10:AK10) -> 0
A11: Penerimaan Bersih | B11: =SUM(B6:B10) -> 0 | C11: =SUM(C6:C10) -> 0 | D11: =SUM(D6:D10) -> 0 | E11: =SUM(E6:E10) -> 0 | F11: =SUM(F6:F10) -> 0 | G11: =SUM(G6:G10) -> 0 | H11: =SUM(H6:H10) -> 0 | I11: =SUM(I6:I10) -> 0 | ... AK11: =SUM(AK6:AK10) -> 0 | AM11: =SUM(B11:AK11) -> 0 | AN11: =SUM(B11:M11) -> 0 | AO11: =SUM(N11:Y11) -> 0 | AP11: =SUM(Z11:AK11) -> 0
A13: Harga Pokok Penjualan | B13: =Processing!P24 -> #DIV/0! | C13: =Processing!P25 -> #DIV/0! | D13: =Processing!P26 -> #DIV/0! | E13: =Processing!P27 -> #DIV/0! | F13: =Processing!P28 -> #DIV/0! | G13: =Processing!P29 -> #DIV/0! | H13: =Processing!P30 -> #DIV/0! | I13: =Processing!P31 -> #DIV/0! | J13: =Processing!P32 -> #DIV/0! | K13: =Processing!P33 -> #DIV/0! | L13: =Processing!P34 -> #DIV/0! | M13: =Processing!P35 -> #DIV/0! | N13: =B13*(100%+Processing!O18) -> #DIV/0! | O13: =C13*(100%+Processing!O18) -> #DIV/0! | P13: =D13*(100%+Processing!O18) -> #DIV/0! | Q13: =E13*(100%+Processing!O18) -> #DIV/0! | R13: =F13*(100%+Processing!O18) -> #DIV/0! | S13: =G13*(100%+Processing!O18) -> #DIV/0! | T13: =H13*(100%+Processing!O18) -> #DIV/0! | U13: =I13*(100%+Processing!O18) -> #DIV/0! | V13: =J13*(100%+Processing!O18) -> #DIV/0! | W13: =K13*(100%+Processing!O18) -> #DIV/0! | X13: =L13*(100%+Processing!O18) -> #DIV/0! | Y13: =M13*(100%+Processing!O18) -> #DIV/0! | Z13: =N13*(100%+Processing!O19) -> #DIV/0! | AA13: =O13*(100%+Processing!O19) -> #DIV/0! | AB13: =P13*(100%+Processing!O19) -> #DIV/0! | AC13: =Q13*(100%+Processing!O19) -> #DIV/0! | AD13: =R13*(100%+Processing!O19) -> #DIV/0! | AE13: =S13*(100%+Processing!O19) -> #DIV/0! | AF13: =T13*(100%+Processing!O19) -> #DIV/0! | AG13: =U13*(100%+Processing!O19) -> #DIV/0! | AH13: =V13*(100%+Processing!O19) -> #DIV/0! | AI13: =W13*(100%+Processing!O19) -> #DIV/0! | AJ13: =X13*(100%+Processing!O19) -> #DIV/0! | AK13: =Y13*(100%+Processing!O19) -> #DIV/0! | AM13: =SUM(B13:AK13) -> #DIV/0! | AN13: =SUM(B13:M13) -> #DIV/0! | AO13: =SUM(N13:Y13) -> #DIV/0! | AP13: =SUM(Z13:AK13) -> #DIV/0!
A15: =Processing!T4 -> Biaya Akuisisi Pelanggan | B15: =Processing!Q24 -> 0 | C15: =Processing!Q25 -> 0 | D15: =Processing!Q26 -> 0 | E15: =Processing!Q27 -> 0 | F15: =Processing!Q28 -> 0 | G15: =Processing!Q29 -> 0 | H15: =Processing!Q30 -> 0 | I15: =Processing!Q31 -> 0 | J15: =Processing!Q32 -> 0 | K15: =Processing!Q33 -> 0 | L15: =Processing!Q34 -> 0 | M15: =Processing!Q35 -> 0 | N15: =B15*(100%+Processing!O18) -> 0 | O15: =C15*(100%+Processing!O18) -> 0 | P15: =D15*(100%+Processing!O18) -> 0 | Q15: =E15*(100%+Processing!O18) -> 0 | R15: =F15*(100%+Processing!O18) -> 0 | S15: =G15*(100%+Processing!O18) -> 0 | T15: =H15*(100%+Processing!O18) -> 0 | U15: =I15*(100%+Processing!O18) -> 0 | V15: =J15*(100%+Processing!O18) -> 0 | W15: =K15*(100%+Processing!O18) -> 0 | X15: =L15*(100%+Processing!O18) -> 0 | Y15: =M15*(100%+Processing!O18) -> 0 | Z15: =N15*(100%+Processing!O19) -> 0 | AA15: =O15*(100%+Processing!O19) -> 0 | AB15: =P15*(100%+Processing!O19) -> 0 | AC15: =Q15*(100%+Processing!O19) -> 0 | AD15: =R15*(100%+Processing!O19) -> 0 | AE15: =S15*(100%+Processing!O19) -> 0 | AF15: =T15*(100%+Processing!O19) -> 0 | AG15: =U15*(100%+Processing!O19) -> 0 | AH15: =V15*(100%+Processing!O19) -> 0 | AI15: =W15*(100%+Processing!O19) -> 0 | AJ15: =X15*(100%+Processing!O19) -> 0 | AK15: =Y15*(100%+Processing!O19) -> 0 | AM15: =SUM(B15:AK15) -> 0 | AN15: =SUM(B15:M15) -> 0 | AO15: =SUM(N15:Y15) -> 0 | AP15: =SUM(Z15:AK15) -> 0
A16: =Processing!T5 -> Biaya Gaji | B16: =Processing!R24 -> 0 | C16: =Processing!R25 -> 0 | D16: =Processing!R26 -> 0 | E16: =Processing!R27 -> 0 | F16: =Processing!R28 -> 0 | G16: =Processing!R29 -> 0 | H16: =Processing!R30 -> 0 | I16: =Processing!R31 -> 0 | J16: =Processing!R32 -> 0 | K16: =Processing!R33 -> 0 | L16: =Processing!R34 -> 0 | M16: =Processing!R35 -> 0 | N16: =B16*(100%+Processing!O18) -> 0 | O16: =C16*(100%+Processing!O18) -> 0 | P16: =D16*(100%+Processing!O18) -> 0 | Q16: =E16*(100%+Processing!O18) -> 0 | R16: =F16*(100%+Processing!O18) -> 0 | S16: =G16*(100%+Processing!O18) -> 0 | T16: =H16*(100%+Processing!O18) -> 0 | U16: =I16*(100%+Processing!O18) -> 0 | V16: =J16*(100%+Processing!O18) -> 0 | W16: =K16*(100%+Processing!O18) -> 0 | X16: =L16*(100%+Processing!O18) -> 0 | Y16: =M16*(100%+Processing!O18) -> 0 | Z16: =N16*(100%+Processing!O19) -> 0 | AA16: =O16*(100%+Processing!O19) -> 0 | AB16: =P16*(100%+Processing!O19) -> 0 | AC16: =Q16*(100%+Processing!O19) -> 0 | AD16: =R16*(100%+Processing!O19) -> 0 | AE16: =S16*(100%+Processing!O19) -> 0 | AF16: =T16*(100%+Processing!O19) -> 0 | AG16: =U16*(100%+Processing!O19) -> 0 | AH16: =V16*(100%+Processing!O19) -> 0 | AI16: =W16*(100%+Processing!O19) -> 0 | AJ16: =X16*(100%+Processing!O19) -> 0 | AK16: =Y16*(100%+Processing!O19) -> 0 | AM16: =SUM(B16:AK16) -> 0 | AN16: =SUM(B16:M16) -> 0 | AO16: =SUM(N16:Y16) -> 0 | AP16: =SUM(Z16:AK16) -> 0
A17: =Processing!T6 -> 0 | B17: =Processing!S24 -> 0 | C17: =Processing!S25 -> 0 | D17: =Processing!S26 -> 0 | E17: =Processing!S27 -> 0 | F17: =Processing!S28 -> 0 | G17: =Processing!S29 -> 0 | H17: =Processing!S30 -> 0 | I17: =Processing!S31 -> 0 | J17: =Processing!S32 -> 0 | K17: =Processing!S33 -> 0 | L17: =Processing!S34 -> 0 | M17: =Processing!S35 -> 0 | N17: =B17*(100%+Processing!O18) -> 0 | O17: =C17*(100%+Processing!O18) -> 0 | P17: =D17*(100%+Processing!O18) -> 0 | Q17: =E17*(100%+Processing!O18) -> 0 | R17: =F17*(100%+Processing!O18) -> 0 | S17: =G17*(100%+Processing!O18) -> 0 | T17: =H17*(100%+Processing!O18) -> 0 | U17: =I17*(100%+Processing!O18) -> 0 | V17: =J17*(100%+Processing!O18) -> 0 | W17: =K17*(100%+Processing!O18) -> 0 | X17: =L17*(100%+Processing!O18) -> 0 | Y17: =M17*(100%+Processing!O18) -> 0 | Z17: =N17*(100%+Processing!O19) -> 0 | AA17: =O17*(100%+Processing!O19) -> 0 | AB17: =P17*(100%+Processing!O19) -> 0 | AC17: =Q17*(100%+Processing!O19) -> 0 | AD17: =R17*(100%+Processing!O19) -> 0 | AE17: =S17*(100%+Processing!O19) -> 0 | AF17: =T17*(100%+Processing!O19) -> 0 | AG17: =U17*(100%+Processing!O19) -> 0 | AH17: =V17*(100%+Processing!O19) -> 0 | AI17: =W17*(100%+Processing!O19) -> 0 | AJ17: =X17*(100%+Processing!O19) -> 0 | AK17: =Y17*(100%+Processing!O19) -> 0 | AM17: =SUM(B17:AK17) -> 0 | AN17: =SUM(B17:M17) -> 0 | AO17: =SUM(N17:Y17) -> 0 | AP17: =SUM(Z17:AK17) -> 0
A18: =Processing!T7 -> 0 | B18: =Processing!T24 -> 0 | C18: =Processing!T25 -> 0 | D18: =Processing!T26 -> 0 | E18: =Processing!T27 -> 0 | F18: =Processing!T28 -> 0 | G18: =Processing!T29 -> 0 | H18: =Processing!T30 -> 0 | I18: =Processing!T31 -> 0 | J18: =Processing!T32 -> 0 | K18: =Processing!T33 -> 0 | L18: =Processing!T34 -> 0 | M18: =Processing!T35 -> 0 | N18: =B18*(100%+Processing!O18) -> 0 | O18: =C18*(100%+Processing!O18) -> 0 | P18: =D18*(100%+Processing!O18) -> 0 | Q18: =E18*(100%+Processing!O18) -> 0 | R18: =F18*(100%+Processing!O18) -> 0 | S18: =G18*(100%+Processing!O18) -> 0 | T18: =H18*(100%+Processing!O18) -> 0 | U18: =I18*(100%+Processing!O18) -> 0 | V18: =J18*(100%+Processing!O18) -> 0 | W18: =K18*(100%+Processing!O18) -> 0 | X18: =L18*(100%+Processing!O18) -> 0 | Y18: =M18*(100%+Processing!O18) -> 0 | Z18: =N18*(100%+Processing!O19) -> 0 | AA18: =O18*(100%+Processing!O19) -> 0 | AB18: =P18*(100%+Processing!O19) -> 0 | AC18: =Q18*(100%+Processing!O19) -> 0 | AD18: =R18*(100%+Processing!O19) -> 0 | AE18: =S18*(100%+Processing!O19) -> 0 | AF18: =T18*(100%+Processing!O19) -> 0 | AG18: =U18*(100%+Processing!O19) -> 0 | AH18: =V18*(100%+Processing!O19) -> 0 | AI18: =W18*(100%+Processing!O19) -> 0 | AJ18: =X18*(100%+Processing!O19) -> 0 | AK18: =Y18*(100%+Processing!O19) -> 0 | AM18: =SUM(B18:AK18) -> 0 | AN18: =SUM(B18:M18) -> 0 | AO18: =SUM(N18:Y18) -> 0 | AP18: =SUM(Z18:AK18) -> 0
A19: =Processing!T8 -> 0 | B19: =Processing!U24 -> 0 | C19: =Processing!U25 -> 0 | D19: =Processing!U26 -> 0 | E19: =Processing!U27 -> 0 | F19: =Processing!U28 -> 0 | G19: =Processing!U29 -> 0 | H19: =Processing!U30 -> 0 | I19: =Processing!U31 -> 0 | J19: =Processing!U32 -> 0 | K19: =Processing!U33 -> 0 | L19: =Processing!U34 -> 0 | M19: =Processing!U35 -> 0 | N19: =B19*(100%+Processing!O18) -> 0 | O19: =C19*(100%+Processing!O18) -> 0 | P19: =D19*(100%+Processing!O18) -> 0 | Q19: =E19*(100%+Processing!O18) -> 0 | R19: =F19*(100%+Processing!O18) -> 0 | S19: =G19*(100%+Processing!O18) -> 0 | T19: =H19*(100%+Processing!O18) -> 0 | U19: =I19*(100%+Processing!O18) -> 0 | V19: =J19*(100%+Processing!O18) -> 0 | W19: =K19*(100%+Processing!O18) -> 0 | X19: =L19*(100%+Processing!O18) -> 0 | Y19: =M19*(100%+Processing!O18) -> 0 | Z19: =N19*(100%+Processing!O19) -> 0 | AA19: =O19*(100%+Processing!O19) -> 0 | AB19: =P19*(100%+Processing!O19) -> 0 | AC19: =Q19*(100%+Processing!O19) -> 0 | AD19: =R19*(100%+Processing!O19) -> 0 | AE19: =S19*(100%+Processing!O19) -> 0 | AF19: =T19*(100%+Processing!O19) -> 0 | AG19: =U19*(100%+Processing!O19) -> 0 | AH19: =V19*(100%+Processing!O19) -> 0 | AI19: =W19*(100%+Processing!O19) -> 0 | AJ19: =X19*(100%+Processing!O19) -> 0 | AK19: =Y19*(100%+Processing!O19) -> 0 | AM19: =SUM(B19:AK19) -> 0 | AN19: =SUM(B19:M19) -> 0 | AO19: =SUM(N19:Y19) -> 0 | AP19: =SUM(Z19:AK19) -> 0
A20: =Processing!T9 -> 0 | B20: =Processing!V24 -> 0 | C20: =Processing!V25 -> 0 | D20: =Processing!V26 -> 0 | E20: =Processing!V27 -> 0 | F20: =Processing!V28 -> 0 | G20: =Processing!V29 -> 0 | H20: =Processing!V30 -> 0 | I20: =Processing!V31 -> 0 | J20: =Processing!V32 -> 0 | K20: =Processing!V33 -> 0 | L20: =Processing!V34 -> 0 | M20: =Processing!V35 -> 0 | N20: =B20*(100%+Processing!O18) -> 0 | O20: =C20*(100%+Processing!O18) -> 0 | P20: =D20*(100%+Processing!O18) -> 0 | Q20: =E20*(100%+Processing!O18) -> 0 | R20: =F20*(100%+Processing!O18) -> 0 | S20: =G20*(100%+Processing!O18) -> 0 | T20: =H20*(100%+Processing!O18) -> 0 | U20: =I20*(100%+Processing!O18) -> 0 | V20: =J20*(100%+Processing!O18) -> 0 | W20: =K20*(100%+Processing!O18) -> 0 | X20: =L20*(100%+Processing!O18) -> 0 | Y20: =M20*(100%+Processing!O18) -> 0 | Z20: =N20*(100%+Processing!O19) -> 0 | AA20: =O20*(100%+Processing!O19) -> 0 | AB20: =P20*(100%+Processing!O19) -> 0 | AC20: =Q20*(100%+Processing!O19) -> 0 | AD20: =R20*(100%+Processing!O19) -> 0 | AE20: =S20*(100%+Processing!O19) -> 0 | AF20: =T20*(100%+Processing!O19) -> 0 | AG20: =U20*(100%+Processing!O19) -> 0 | AH20: =V20*(100%+Processing!O19) -> 0 | AI20: =W20*(100%+Processing!O19) -> 0 | AJ20: =X20*(100%+Processing!O19) -> 0 | AK20: =Y20*(100%+Processing!O19) -> 0 | AM20: =SUM(B20:AK20) -> 0 | AN20: =SUM(B20:M20) -> 0 | AO20: =SUM(N20:Y20) -> 0 | AP20: =SUM(Z20:AK20) -> 0
A21: =Processing!T10 -> 0 | B21: =Processing!W24 -> 0 | C21: =Processing!W25 -> 0 | D21: =Processing!W26 -> 0 | E21: =Processing!W27 -> 0 | F21: =Processing!W28 -> 0 | G21: =Processing!W29 -> 0 | H21: =Processing!W30 -> 0 | I21: =Processing!W31 -> 0 | J21: =Processing!W32 -> 0 | K21: =Processing!W33 -> 0 | L21: =Processing!W34 -> 0 | M21: =Processing!W35 -> 0 | N21: =B21*(100%+Processing!O18) -> 0 | O21: =C21*(100%+Processing!O18) -> 0 | P21: =D21*(100%+Processing!O18) -> 0 | Q21: =E21*(100%+Processing!O18) -> 0 | R21: =F21*(100%+Processing!O18) -> 0 | S21: =G21*(100%+Processing!O18) -> 0 | T21: =H21*(100%+Processing!O18) -> 0 | U21: =I21*(100%+Processing!O18) -> 0 | V21: =J21*(100%+Processing!O18) -> 0 | W21: =K21*(100%+Processing!O18) -> 0 | X21: =L21*(100%+Processing!O18) -> 0 | Y21: =M21*(100%+Processing!O18) -> 0 | Z21: =N21*(100%+Processing!O19) -> 0 | AA21: =O21*(100%+Processing!O19) -> 0 | AB21: =P21*(100%+Processing!O19) -> 0 | AC21: =Q21*(100%+Processing!O19) -> 0 | AD21: =R21*(100%+Processing!O19) -> 0 | AE21: =S21*(100%+Processing!O19) -> 0 | AF21: =T21*(100%+Processing!O19) -> 0 | AG21: =U21*(100%+Processing!O19) -> 0 | AH21: =V21*(100%+Processing!O19) -> 0 | AI21: =W21*(100%+Processing!O19) -> 0 | AJ21: =X21*(100%+Processing!O19) -> 0 | AK21: =Y21*(100%+Processing!O19) -> 0 | AM21: =SUM(B21:AK21) -> 0 | AN21: =SUM(B21:M21) -> 0 | AO21: =SUM(N21:Y21) -> 0 | AP21: =SUM(Z21:AK21) -> 0
A22: =Processing!T11 -> 0 | B22: =Processing!X24 -> 0 | C22: =Processing!X25 -> 0 | D22: =Processing!X26 -> 0 | E22: =Processing!X27 -> 0 | F22: =Processing!X28 -> 0 | G22: =Processing!X29 -> 0 | H22: =Processing!X30 -> 0 | I22: =Processing!X31 -> 0 | J22: =Processing!X32 -> 0 | K22: =Processing!X33 -> 0 | L22: =Processing!X34 -> 0 | M22: =Processing!X35 -> 0 | N22: =B22*(100%+Processing!O18) -> 0 | O22: =C22*(100%+Processing!O18) -> 0 | P22: =D22*(100%+Processing!O18) -> 0 | Q22: =E22*(100%+Processing!O18) -> 0 | R22: =F22*(100%+Processing!O18) -> 0 | S22: =G22*(100%+Processing!O18) -> 0 | T22: =H22*(100%+Processing!O18) -> 0 | U22: =I22*(100%+Processing!O18) -> 0 | V22: =J22*(100%+Processing!O18) -> 0 | W22: =K22*(100%+Processing!O18) -> 0 | X22: =L22*(100%+Processing!O18) -> 0 | Y22: =M22*(100%+Processing!O18) -> 0 | Z22: =N22*(100%+Processing!O19) -> 0 | AA22: =O22*(100%+Processing!O19) -> 0 | AB22: =P22*(100%+Processing!O19) -> 0 | AC22: =Q22*(100%+Processing!O19) -> 0 | AD22: =R22*(100%+Processing!O19) -> 0 | AE22: =S22*(100%+Processing!O19) -> 0 | AF22: =T22*(100%+Processing!O19) -> 0 | AG22: =U22*(100%+Processing!O19) -> 0 | AH22: =V22*(100%+Processing!O19) -> 0 | AI22: =W22*(100%+Processing!O19) -> 0 | AJ22: =X22*(100%+Processing!O19) -> 0 | AK22: =Y22*(100%+Processing!O19) -> 0 | AM22: =SUM(B22:AK22) -> 0 | AN22: =SUM(B22:M22) -> 0 | AO22: =SUM(N22:Y22) -> 0 | AP22: =SUM(Z22:AK22) -> 0
A23: =Processing!T12 -> 0 | B23: =Processing!Y24 -> 0 | C23: =Processing!Y25 -> 0 | D23: =Processing!Y26 -> 0 | E23: =Processing!Y27 -> 0 | F23: =Processing!Y28 -> 0 | G23: =Processing!Y29 -> 0 | H23: =Processing!Y30 -> 0 | I23: =Processing!Y31 -> 0 | J23: =Processing!Y32 -> 0 | K23: =Processing!Y33 -> 0 | L23: =Processing!Y34 -> 0 | M23: =Processing!Y35 -> 0 | N23: =B23*(100%+Processing!O18) -> 0 | O23: =C23*(100%+Processing!O18) -> 0 | P23: =D23*(100%+Processing!O18) -> 0 | Q23: =E23*(100%+Processing!O18) -> 0 | R23: =F23*(100%+Processing!O18) -> 0 | S23: =G23*(100%+Processing!O18) -> 0 | T23: =H23*(100%+Processing!O18) -> 0 | U23: =I23*(100%+Processing!O18) -> 0 | V23: =J23*(100%+Processing!O18) -> 0 | W23: =K23*(100%+Processing!O18) -> 0 | X23: =L23*(100%+Processing!O18) -> 0 | Y23: =M23*(100%+Processing!O18) -> 0 | Z23: =N23*(100%+Processing!O19) -> 0 | AA23: =O23*(100%+Processing!O19) -> 0 | AB23: =P23*(100%+Processing!O19) -> 0 | AC23: =Q23*(100%+Processing!O19) -> 0 | AD23: =R23*(100%+Processing!O19) -> 0 | AE23: =S23*(100%+Processing!O19) -> 0 | AF23: =T23*(100%+Processing!O19) -> 0 | AG23: =U23*(100%+Processing!O19) -> 0 | AH23: =V23*(100%+Processing!O19) -> 0 | AI23: =W23*(100%+Processing!O19) -> 0 | AJ23: =X23*(100%+Processing!O19) -> 0 | AK23: =Y23*(100%+Processing!O19) -> 0 | AM23: =SUM(B23:AK23) -> 0 | AN23: =SUM(B23:M23) -> 0 | AO23: =SUM(N23:Y23) -> 0 | AP23: =SUM(Z23:AK23) -> 0
A24: Total Biaya Tidak Langsung | B24: =SUM(B15:B23) -> 0 | C24: =SUM(C15:C23) -> 0 | D24: =SUM(D15:D23) -> 0 | E24: =SUM(E15:E23) -> 0 | F24: =SUM(F15:F23) -> 0 | G24: =SUM(G15:G23) -> 0 | H24: =SUM(H15:H23) -> 0 | I24: =SUM(I15:I23) -> 0 | ... AK24: =SUM(AK15:AK23) -> 0 | AM24: =SUM(B24:AK24) -> 0 | AN24: =SUM(B24:M24) -> 0 | AO24: =SUM(N24:Y24) -> 0 | AP24: =SUM(Z24:AK24) -> 0
A26: Pendapatan Kotor (EBITDA) | B26: =B11-(B13+B24) -> #DIV/0! | C26: =C11-(C13+C24) -> #DIV/0! | D26: =D11-(D13+D24) -> #DIV/0! | E26: =E11-(E13+E24) -> #DIV/0! | F26: =F11-(F13+F24) -> #DIV/0! | G26: =G11-(G13+G24) -> #DIV/0! | H26: =H11-(H13+H24) -> #DIV/0! | I26: =I11-(I13+I24) -> #DIV/0! | ... AK26: =AK11-(AK13+AK24) -> #DIV/0! | AM26: =SUM(B26:AK26) -> #DIV/0! | AN26: =SUM(B26:M26) -> #DIV/0! | AO26: =SUM(N26:Y26) -> #DIV/0! | AP26: =SUM(Z26:AK26) -> #DIV/0!
A28: Biaya Pajak | B28: =Processing!J13*'Proyeksi Arus Kas'!B26 -> #DIV/0! | C28: =C26*Processing!J13 -> #DIV/0! | D28: =D26*Processing!J13 -> #DIV/0! | E28: =E26*Processing!J13 -> #DIV/0! | F28: =F26*Processing!J13 -> #DIV/0! | G28: =G26*Processing!J13 -> #DIV/0! | H28: =H26*Processing!J13 -> #DIV/0! | I28: =I26*Processing!J13 -> #DIV/0! | J28: =J26*Processing!J13 -> #DIV/0! | K28: =K26*Processing!J13 -> #DIV/0! | L28: =L26*Processing!J13 -> #DIV/0! | M28: =M26*Processing!J13 -> #DIV/0! | N28: =N26*Processing!J13 -> #DIV/0! | O28: =O26*Processing!J13 -> #DIV/0! | P28: =P26*Processing!J13 -> #DIV/0! | Q28: =Q26*Processing!J13 -> #DIV/0! | R28: =R26*Processing!J13 -> #DIV/0! | S28: =S26*Processing!J13 -> #DIV/0! | T28: =T26*Processing!J13 -> #DIV/0! | U28: =U26*Processing!J13 -> #DIV/0! | V28: =V26*Processing!J13 -> #DIV/0! | W28: =W26*Processing!J13 -> #DIV/0! | X28: =X26*Processing!J13 -> #DIV/0! | Y28: =Y26*Processing!J13 -> #DIV/0! | Z28: =Z26*Processing!J13 -> #DIV/0! | AA28: =AA26*Processing!J13 -> #DIV/0! | AB28: =AB26*Processing!J13 -> #DIV/0! | AC28: =AC26*Processing!J13 -> #DIV/0! | AD28: =AD26*Processing!J13 -> #DIV/0! | AE28: =AE26*Processing!J13 -> #DIV/0! | AF28: =AF26*Processing!J13 -> #DIV/0! | AG28: =AG26*Processing!J13 -> #DIV/0! | AH28: =AH26*Processing!J13 -> #DIV/0! | AI28: =AI26*Processing!J13 -> #DIV/0! | AJ28: =AJ26*Processing!J13 -> #DIV/0! | AK28: =AK26*Processing!J13 -> #DIV/0! | AM28: =SUM(B28:AK28) -> #DIV/0! | AN28: =SUM(B28:M28) -> #DIV/0! | AO28: =SUM(N28:Y28) -> #DIV/0! | AP28: =SUM(Z28:AK28) -> #DIV/0!
A29: Biaya Bunga | B29: =(Navigasi!D12*Navigasi!C8)/36 -> 0 | C29: =B29 -> 0 | D29: =C29 -> 0 | E29: =D29 -> 0 | F29: =E29 -> 0 | G29: =F29 -> 0 | H29: =G29 -> 0 | I29: =H29 -> 0 | J29: =I29 -> 0 | ... AK29: =AJ29 -> 0 | AM29: =SUM(B29:AK29) -> 0 | AN29: =SUM(B29:M29) -> 0 | AO29: =SUM(N29:Y29) -> 0 | AP29: =SUM(Z29:AK29) -> 0
A30: Depresiasi | B30: =(Navigasi!D16*Navigasi!C16)/36 -> 0 | C30: =B30 -> 0 | D30: =C30 -> 0 | E30: =D30 -> 0 | F30: =E30 -> 0 | G30: =F30 -> 0 | H30: =G30 -> 0 | I30: =H30 -> 0 | J30: =I30 -> 0 | ... AK30: =AJ30 -> 0 | AM30: =SUM(B30:AK30) -> 0 | AN30: =SUM(B30:M30) -> 0 | AO30: =SUM(N30:Y30) -> 0 | AP30: =SUM(Z30:AK30) -> 0
A31: Amortisasi | B31: =(Navigasi!D14*Navigasi!C15)/36 -> 0 | C31: =B31 -> 0 | D31: =C31 -> 0 | E31: =D31 -> 0 | F31: =E31 -> 0 | G31: =F31 -> 0 | H31: =G31 -> 0 | I31: =H31 -> 0 | J31: =I31 -> 0 | ... AK31: =AJ31 -> 0 | AM31: =SUM(B31:AK31) -> 0 | AN31: =SUM(B31:M31) -> 0 | AO31: =SUM(N31:Y31) -> 0 | AP31: =SUM(Z31:AK31) -> 0
B32: =SUM(B28:B31) -> #DIV/0! | C32: =SUM(C28:C31) -> #DIV/0! | D32: =SUM(D28:D31) -> #DIV/0! | E32: =SUM(E28:E31) -> #DIV/0! | F32: =SUM(F28:F31) -> #DIV/0! | G32: =SUM(G28:G31) -> #DIV/0! | H32: =SUM(H28:H31) -> #DIV/0! | I32: =SUM(I28:I31) -> #DIV/0! | ... AK32: =SUM(AK28:AK31) -> #DIV/0! | AM32: =SUM(B32:AK32) -> #DIV/0! | AN32: =SUM(B32:M32) -> #DIV/0! | AO32: =SUM(N32:Y32) -> #DIV/0! | AP32: =SUM(Z32:AK32) -> #DIV/0!
A34: Laba Bersih | B34: =B26-B32 -> #DIV/0! | C34: =C26-C32 -> #DIV/0! | D34: =D26-D32 -> #DIV/0! | E34: =E26-E32 -> #DIV/0! | F34: =F26-F32 -> #DIV/0! | G34: =G26-G32 -> #DIV/0! | H34: =H26-H32 -> #DIV/0! | I34: =I26-I32 -> #DIV/0! | ... AK34: =AK26-AK32 -> #DIV/0! | AM34: =SUM(B34:AK34) -> #DIV/0! | AN34: =SUM(B34:M34) -> #DIV/0! | AO34: =SUM(N34:Y34) -> #DIV/0! | AP34: =SUM(Z34:AK34) -> #DIV/0!

Sheet Processing
B3: PENERIMAAN BERSIH PER TAHUN | J3: HARGA POKOK PRODUKSI | S3: BIAYA TIDAK LANGSUNG
B4: No | C4: Nama Produk | D4: Harga Jual Per Unit | E4: % Contribution | F4: Target Penjualan tahunan (unit) | G4: Jumlah | L4: =Navigasi!B30 -> 0 | M4: =Navigasi!B31 -> 0 | N4: =Navigasi!B32 -> 0 | O4: =Navigasi!B33 -> 0 | P4: =Navigasi!B34 -> 0 | Q4: HPP Per Unit | S4: 1 | T4: =Navigasi!G16 -> Biaya Akuisisi Pelanggan
B5: 1 | C5: =Navigasi!B20 -> 0 | D5: =Navigasi!C20 -> 0 | E5: =Navigasi!D20 -> 0 | F5: =G5/D5 -> #DIV/0! | G5: =E5*G12 -> 0 | J5: 1 | K5: =C5 -> 0 | L5: =Navigasi!C30 -> 0 | M5: =Navigasi!C31 -> 0 | N5: =Navigasi!C32 -> 0 | O5: =Navigasi!C33 -> 0 | P5: =Navigasi!C34 -> 0 | Q5: =SUM(L5:P5) -> 0 | S5: 2 | T5: =Navigasi!G17 -> Biaya Gaji
B6: 2 | C6: =Navigasi!B21 -> 0 | D6: =Navigasi!C21 -> 0 | E6: =Navigasi!D21 -> 0 | F6: =G6/D6 -> #DIV/0! | G6: =E6*G12 -> 0 | J6: 2 | K6: =C6 -> 0 | L6: =Navigasi!D30 -> 0 | M6: =Navigasi!D31 -> 0 | N6: =Navigasi!D32 -> 0 | O6: =Navigasi!D33 -> 0 | P6: =Navigasi!D34 -> 0 | Q6: =SUM(L6:P6) -> 0 | S6: 3 | T6: =Navigasi!G18 -> 0
B7: 3 | C7: =Navigasi!B22 -> 0 | D7: =Navigasi!C22 -> 0 | E7: =Navigasi!D22 -> 0 | F7: =G7/D7 -> #DIV/0! | G7: =E7*G12 -> 0 | J7: 3 | K7: =C7 -> 0 | L7: =Navigasi!E30 -> 0 | M7: =Navigasi!E31 -> 0 | N7: =Navigasi!E32 -> 0 | O7: =Navigasi!E33 -> 0 | P7: =Navigasi!E34 -> 0 | Q7: =SUM(L7:P7) -> 0 | S7: 4 | T7: =Navigasi!G19 -> 0
B8: 4 | C8: =Navigasi!B23 -> 0 | D8: =Navigasi!C23 -> 0 | E8: =Navigasi!D23 -> 0 | F8: =G8/D8 -> #DIV/0! | G8: =E8*G12 -> 0 | J8: 4 | K8: =C8 -> 0 | L8: =Navigasi!H30 -> 0 | M8: =Navigasi!H31 -> 0 | N8: =Navigasi!H32 -> 0 | O8: =Navigasi!H33 -> 0 | P8: =Navigasi!H34 -> 0 | Q8: =SUM(L8:P8) -> 0 | S8: 5 | T8: =Navigasi!G20 -> 0
B9: 5 | C9: =Navigasi!B24 -> 0 | D9: =Navigasi!C24 -> 0 | E9: =Navigasi!D24 -> 0 | F9: =G9/D9 -> #DIV/0! | G9: =E9*G12 -> 0 | J9: 5 | K9: =C9 -> 0 | L9: =Navigasi!I30 -> 0 | M9: =Navigasi!I31 -> 0 | N9: =Navigasi!I32 -> 0 | O9: =Navigasi!I33 -> 0 | P9: =Navigasi!I34 -> 0 | Q9: =SUM(L9:P9) -> 0 | S9: 6 | T9: =Navigasi!G21 -> 0
G10: =E10*G12 -> 0 | S10: 7 | T10: =Navigasi!G22 -> 0
E11: =SUM(E5:E10) -> 0 | S11: 8 | T11: =Navigasi!G23 -> 0
B12: Total Penerimaa Bersih | G12: =E36 -> 0 | J12: BIAYA PAJAK | S12: 9 | T12: =Navigasi!G24 -> 0
J13: =Navigasi!C12 -> 0
B14: Ratio Kontribusi
C15: Tahun 1 | D15: Tahun 2 | E15: Tahun 3 | F15: Total
B16: Kontribusi | C16: =Navigasi!H9 -> 0 | D16: =Navigasi!H10 -> 0 | E16: =Navigasi!H11 -> 0
B17: StartUp | C17: =C16*F17 -> 0 | D17: =D16*F17 -> 0 | E17: =E16*F17 -> 0 | F17: =Navigasi!K7 -> 0
J18: Perkiraan peningkatan Biaya Tahun kedua | O18: =Navigasi!C13 -> 0
C19: Kurs Rupiah per 1 USD | F19: =Navigasi!J12 -> 0 | J19: Perkiraan Peningkatan Biaya Tahun Ketiga | O19: =Navigasi!C14 -> 0
F20: =F17/F19 -> #DIV/0!
I22: TARGET PENJUALAN PER BULAN (UNIT)
B23: No | C23: Bulan | D23: % kontribusi bulanan | E23: Tahun 1 | F23: Tahun 2 | G23: Tahun 3 | K23: =C5 -> 0 | L23: =C6 -> 0 | M23: =C7 -> 0 | N23: =C8 -> 0 | O23: =C9 -> 0 | P23: HPP TOTAL | Q23: =T4 -> Biaya Akuisisi Pelanggan | R23: =T5 -> Biaya Gaji | S23: =T6 -> 0 | T23: =T7 -> 0 | U23: =T8 -> 0 | V23: =T9 -> 0 | W23: =T10 -> 0 | X23: =T11 -> 0 | Y23: =T12 -> 0
B24: 1 | C24: Januari | D24: =Navigasi!M16 -> 0 | E24: =D24*C17 -> 0 | F24: =D24*D17 -> 0 | G24: =D24*E17 -> 0 | I24: 1 | J24: =Navigasi!L16 -> JANUARI | K24: =(E5*E24)/D5 -> #DIV/0! | L24: =(E6*E24)/D6 -> #DIV/0! | M24: =(E7*E24)/D7 -> #DIV/0! | N24: =(E8*E24)/D8 -> #DIV/0! | O24: =(E9*E24)/D9 -> #DIV/0! | P24: =(K24*Q5)+(L24*Q6)+(M24*Q7)+(N24*Q8)+(O24*Q9) -> #DIV/0! | Q24: =Navigasi!J16 -> 0 | R24: =Navigasi!J17 -> 0 | S24: =Navigasi!J18 -> 0 | T24: =Navigasi!J19 -> 0 | U24: =Navigasi!J20 -> 0 | V24: =Navigasi!J21 -> 0 | W24: =Navigasi!J22 -> 0 | X24: =Navigasi!J23 -> 0 | Y24: =Navigasi!J24 -> 0
B25: 2 | C25: Februari | D25: =Navigasi!M17 -> 0 | E25: =D25*C17 -> 0 | F25: =D25*D17 -> 0 | G25: =D25*E17 -> 0 | I25: 2 | J25: =Navigasi!L17 -> FEBRUARI | K25: =(E5*E25)/D5 -> #DIV/0! | L25: =(E6*E25)/D6 -> #DIV/0! | M25: =(E7*E25)/D7 -> #DIV/0! | N25: =(E8*E25)/D8 -> #DIV/0! | O25: =(E9*E25)/D9 -> #DIV/0! | P25: =(K25*Q5)+(L25*Q6)+(M25*Q7)+(N25*Q8)+(O25*Q9) -> #DIV/0! | Q25: =Navigasi!J16 -> 0 | R25: =Navigasi!J17 -> 0 | S25: =Navigasi!J18 -> 0 | T25: =Navigasi!J19 -> 0 | U25: =U24 -> 0 | V25: =V24 -> 0 | W25: =W24 -> 0 | X25: =X24 -> 0 | Y25: =Navigasi!J24 -> 0
B26: 3 | C26: Maret | D26: =Navigasi!M18 -> 0 | E26: =D26*C17 -> 0 | F26: =D26*D17 -> 0 | G26: =D26*E17 -> 0 | I26: 3 | J26: =Navigasi!L18 -> MARET | K26: =(E5*E26)/D5 -> #DIV/0! | L26: =(E6*E26)/D6 -> #DIV/0! | M26: =(E7*E26)/D7 -> #DIV/0! | N26: =(E8*E26)/D8 -> #DIV/0! | O26: =(E9*E26)/D9 -> #DIV/0! | P26: =(K26*Q5)+(Q6*L26)+(M26*Q7)+(N26*Q8)+(O26*Q9) -> #DIV/0! | Q26: =Q25 -> 0 | R26: =R25 -> 0 | S26: =S25 -> 0 | T26: =T25 -> 0 | U26: =U25 -> 0 | V26: =V25 -> 0 | W26: =W25 -> 0 | X26: =X25 -> 0 | Y26: =Y25 -> 0
B27: 4 | C27: April | D27: =Navigasi!M19 -> 0 | E27: =D27*C17 -> 0 | F27: =D27*D17 -> 0 | G27: =D27*E17 -> 0 | I27: 4 | J27: =Navigasi!L19 -> APRIL | K27: =(E5*E27)/D5 -> #DIV/0! | L27: =(E6*E27)/D6 -> #DIV/0! | M27: =(E7*E27)/D7 -> #DIV/0! | N27: =(E8*E27)/D8 -> #DIV/0! | O27: =(E9*E27)/D9 -> #DIV/0! | P27: =(K27*Q5)+(Q6*L27)+(M27*Q7)+(Q8*N27)+(O27*Q9) -> #DIV/0! | Q27: =Q26 -> 0 | R27: =R26 -> 0 | S27: =S26 -> 0 | T27: =T26 -> 0 | U27: =U26 -> 0 | V27: =V26 -> 0 | W27: =W26 -> 0 | X27: =X26 -> 0 | Y27: =Y26 -> 0
B28: 5 | C28: Mei | D28: =Navigasi!M20 -> 0 | E28: =D28*C17 -> 0 | F28: =D28*D17 -> 0 | G28: =D28*E17 -> 0 | I28: 5 | J28: =Navigasi!L20 -> MEI | K28: =(E5*E28)/D5 -> #DIV/0! | L28: =(E6*E28)/D6 -> #DIV/0! | M28: =(E7*E28)/D7 -> #DIV/0! | N28: =(E8*E28)/D8 -> #DIV/0! | O28: =(E9*E28)/D9 -> #DIV/0! | P28: =(K28*Q5)+(Q6*L28)+(M28*Q7)+(Q8*N28)+(O28*Q9) -> #DIV/0! | Q28: =Q27 -> 0 | R28: =R27 -> 0 | S28: =S27 -> 0 | T28: =T27 -> 0 | U28: =U27 -> 0 | V28: =V27 -> 0 | W28: =W27 -> 0 | X28: =X27 -> 0 | Y28: =Y27 -> 0
B29: 6 | C29: Juni | D29: =Navigasi!M21 -> 0 | E29: =D29*C17 -> 0 | F29: =D29*D17 -> 0 | G29: =D29*E17 -> 0 | I29: 6 | J29: =Navigasi!L21 -> JUNI | K29: =(E5*E29)/D5 -> #DIV/0! | L29: =(E6*E29)/D6 -> #DIV/0! | M29: =(E7*E29)/D7 -> #DIV/0! | N29: =(E8*E29)/D8 -> #DIV/0! | O29: =(E9*E29)/D9 -> #DIV/0! | P29: =(K29*Q5)+(Q6*L29)+(M29*Q7)+(Q8*N29)+(O29*Q9) -> #DIV/0! | Q29: =Q28 -> 0 | R29: =R28 -> 0 | S29: =S28 -> 0 | T29: =T28 -> 0 | U29: =U28 -> 0 | V29: =V28 -> 0 | W29: =W28 -> 0 | X29: =X28 -> 0 | Y29: =Y28 -> 0
B30: 7 | C30: Juli | D30: =Navigasi!M22 -> 0 | E30: =D30*C17 -> 0 | F30: =D30*D17 -> 0 | G30: =D30*E17 -> 0 | I30: 7 | J30: =Navigasi!L22 -> JULI | K30: =(E30*E5)/D5 -> #DIV/0! | L30: =(E6*E30)/D6 -> #DIV/0! | M30: =(E7*E30)/D7 -> #DIV/0! | N30: =(E8*E30)/D8 -> #DIV/0! | O30: =(E9*E30)/D9 -> #DIV/0! | P30: =(K30*Q5)+(Q6*L30)+(M30*Q7)+(Q8*N30)+(O30*Q9) -> #DIV/0! | Q30: =Q29 -> 0 | R30: =R29 -> 0 | S30: =S29 -> 0 | T30: =T29 -> 0 | U30: =U29 -> 0 | V30: =V29 -> 0 | W30: =W29 -> 0 | X30: =X29 -> 0 | Y30: =Y29 -> 0
B31: 8 | C31: Agustus | D31: =Navigasi!M23 -> 0 | E31: =D31*C17 -> 0 | F31: =D31*D17 -> 0 | G31: =D31*E17 -> 0 | I31: 8 | J31: =Navigasi!L23 -> AGUSTUS | K31: =(E5*E31)/D5 -> #DIV/0! | L31: =(E6*E31)/D6 -> #DIV/0! | M31: =(E7*E31)/D7 -> #DIV/0! | N31: =(E8*E31)/D8 -> #DIV/0! | O31: =(E9*E31)/D9 -> #DIV/0! | P31: =(K31*Q5)+(Q6*L31)+(M31*Q7)+(Q8*N31)+(O31*Q9) -> #DIV/0! | Q31: =Q30 -> 0 | R31: =R30 -> 0 | S31: =S30 -> 0 | T31: =T30 -> 0 | U31: =U30 -> 0 | V31: =V30 -> 0 | W31: =W30 -> 0 | X31: =X30 -> 0 | Y31: =Y30 -> 0
B32: 9 | C32: September | D32: =Navigasi!M24 -> 0 | E32: =D32*C17 -> 0 | F32: =D32*D17 -> 0 | G32: =D32*E17 -> 0 | I32: 9 | J32: =Navigasi!L24 -> SEPTEMBER | K32: =(E5*E32)/D5 -> #DIV/0! | L32: =(E6*E32)/D6 -> #DIV/0! | M32: =(E7*E32)/D7 -> #DIV/0! | N32: =(E8*E32)/D8 -> #DIV/0! | O32: =(E9*E32)/D9 -> #DIV/0! | P32: =(K32*Q5)+(Q6*L32)+(M32*Q7)+(N32*Q8)+(Q9*O32) -> #DIV/0! | Q32: =Q31 -> 0 | R32: =R31 -> 0 | S32: =S31 -> 0 | T32: =T31 -> 0 | U32: =U31 -> 0 | V32: =V31 -> 0 | W32: =W31 -> 0 | X32: =X31 -> 0 | Y32: =Y31 -> 0
B33: 10 | C33: Oktober | D33: =Navigasi!M25 -> 0 | E33: =D33*C17 -> 0 | F33: =D33*D17 -> 0 | G33: =D33*E17 -> 0 | I33: 10 | J33: =Navigasi!L25 -> OKTOBER | K33: =(E5*E33)/D5 -> #DIV/0! | L33: =(E6*E33)/D6 -> #DIV/0! | M33: =(E7*E33)/D7 -> #DIV/0! | N33: =(E33*E8)/D8 -> #DIV/0! | O33: =(E9*E33)/D9 -> #DIV/0! | P33: =(K33*Q5)+(Q6*L33)+(M33*Q7)+(Q8*N33)+(O33*Q9) -> #DIV/0! | Q33: =Q32 -> 0 | R33: =R32 -> 0 | S33: =S32 -> 0 | T33: =T32 -> 0 | U33: =U32 -> 0 | V33: =V32 -> 0 | W33: =W32 -> 0 | X33: =X32 -> 0 | Y33: =Y32 -> 0
B34: 11 | C34: November | D34: =Navigasi!M26 -> 0 | E34: =D34*C17 -> 0 | F34: =D34*D17 -> 0 | G34: =D34*E17 -> 0 | I34: 11 | J34: =Navigasi!L26 -> NOVEMBER | K34: =(E34*E5)/D5 -> #DIV/0! | L34: =(E6*E34)/D6 -> #DIV/0! | M34: =(E7*E34)/D7 -> #DIV/0! | N34: =(E8*E34)/D8 -> #DIV/0! | O34: =(E9*E34)/D9 -> #DIV/0! | P34: =(K34*Q5)+(Q6*L34)+(M34*Q7)+(Q8*N34)+(O34*Q9) -> #DIV/0! | Q34: =Q33 -> 0 | R34: =R33 -> 0 | S34: =S33 -> 0 | T34: =T33 -> 0 | U34: =U33 -> 0 | V34: =V33 -> 0 | W34: =W33 -> 0 | X34: =X33 -> 0 | Y34: =Y33 -> 0
B35: 12 | C35: Desember | D35: =Navigasi!M27 -> 0 | E35: =D35*C17 -> 0 | F35: =D35*D17 -> 0 | G35: =D35*E17 -> 0 | I35: 12 | J35: =Navigasi!L27 -> DESEMBER | K35: =(E5*E35)/D5 -> #DIV/0! | L35: =(E6*E35)/D6 -> #DIV/0! | M35: =(E35*E7)/D7 -> #DIV/0! | N35: =(E8*E35)/D8 -> #DIV/0! | O35: =(E9*E35)/D9 -> #DIV/0! | P35: =(K35*Q5)+(Q6*L35)+(M35*Q7)+(Q8*N35)+(O35*Q9) -> #DIV/0! | Q35: =Q34 -> 0 | R35: =R34 -> 0 | S35: =S34 -> 0 | T35: =T34 -> 0 | U35: =U34 -> 0 | V35: =V34 -> 0 | W35: =W34 -> 0 | X35: =X34 -> 0 | Y35: =Y34 -> 0
D36: =SUM(D24:D35) -> 0 | E36: =SUM(E24:E35) -> 0 | F36: =SUM(F24:F35) -> 0 | G36: =SUM(G24:G35) -> 0 | K36: =SUM(K24:K35) -> #DIV/0! | L36: =SUM(L24:L35) -> #DIV/0! | M36: =SUM(M24:M35) -> #DIV/0! | N36: =SUM(N24:N35) -> #DIV/0! | O36: =SUM(O24:O35) -> #DIV/0! | P36: =SUM(K36:O36) -> #DIV/0!
J38: BEP DISTRIBUTION
B39: Perkiraan jumlah pelanggan baru pada tahun pertama | L39: Harga Jual | M39: Variabel | N39: %
C40: Tahun 1 | D40: Tahun 2 | E40: Tahun 3 | F40: Total | J40: =C5 -> 0 | L40: =D5 -> 0 | M40: =Q5 -> 0 | N40: =E5 -> 0 | P40: =(L40-M40)*N40 -> 0
B41: Pelanggan | C41: =Navigasi!C11 -> 0 | D41: =D17/(C17/C41) -> #DIV/0! | E41: =E17/(C17/C41) -> #DIV/0! | F41: =SUM(C41:E41) -> #DIV/0! | J41: =C6 -> 0 | L41: =D6 -> 0 | M41: =Q6 -> 0 | N41: =E6 -> 0 | P41: =(L41-M41)*N41 -> 0
B42: Pelanggan baru | C42: =C41 -> 0 | D42: =D41-C41 -> #DIV/0! | E42: =E41-D41 -> #DIV/0! | F42: =SUM(C42:E42) -> #DIV/0! | J42: =C7 -> 0 | L42: =D7 -> 0 | M42: =Q7 -> 0 | N42: =E7 -> 0 | P42: =(L42-M42)*N42 -> 0
J43: =C8 -> 0 | L43: =D8 -> 0 | M43: =Q8 -> 0 | N43: =E8 -> 0 | P43: =(L43-M43)*N43 -> 0
J44: =C9 -> 0 | L44: =D9 -> 0 | M44: =Q9 -> 0 | N44: =E9 -> 0 | P44: =(L44-M44)*N44 -> 0
...
